Time slot   0---------------------------------
ld_routine
Time slot   1---------------------------------
	Loaded a process at input/proc/s4, PID: 1 PRIO: 4
Time slot   2---------------------------------
	Loaded a process at input/proc/s3, PID: 2 PRIO: 3
	CPU 0: Dispatched process  2 at 2
Time slot   3---------------------------------
Time slot   4---------------------------------
	CPU 0: Put process  2 to run queue at 4
	CPU 0: Dispatched process  2 at 4
	Loaded a process at input/proc/m1s, PID: 3 PRIO: 2
Time slot   5---------------------------------
Time slot   6---------------------------------
	Loaded a process at input/proc/s2, PID: 4 PRIO: 3
	CPU 0: Put process  2 to run queue at 6
	CPU 0: Dispatched process  3 at 6
SIZE 300
ALLOC SUCCESS 0 299
Time slot   7---------------------------------
SIZE 100
ALLOC SUCCESS 300 399
	Loaded a process at input/proc/m0s, PID: 5 PRIO: 3
Time slot   8---------------------------------
	CPU 0: Put process  3 to run queue at 8
	CPU 0: Dispatched process  3 at 8
Time slot   9---------------------------------
ALLOC SUCCESS 0 99
	Loaded a process at input/proc/p1s, PID: 6 PRIO: 2
Time slot  10---------------------------------
	CPU 0: Put process  3 to run queue at 10
	CPU 0: Dispatched process  6 at 10
Time slot  11---------------------------------
	Loaded a process at input/proc/s0, PID: 7 PRIO: 1
Time slot  12---------------------------------
	CPU 0: Put process  6 to run queue at 12
	CPU 0: Dispatched process  7 at 12
Time slot  13---------------------------------
Time slot  14---------------------------------
	CPU 0: Put process  7 to run queue at 14
	CPU 0: Dispatched process  7 at 14
Time slot  15---------------------------------
Time slot  16---------------------------------
	CPU 0: Put process  7 to run queue at 16
	CPU 0: Dispatched process  7 at 16
	Loaded a process at input/proc/s1, PID: 8 PRIO: 0
Time slot  17---------------------------------
Time slot  18---------------------------------
	CPU 0: Put process  7 to run queue at 18
	CPU 0: Dispatched process  8 at 18
Time slot  19---------------------------------
Time slot  20---------------------------------
	CPU 0: Put process  8 to run queue at 20
	CPU 0: Dispatched process  8 at 20
Time slot  21---------------------------------
Time slot  22---------------------------------
	CPU 0: Put process  8 to run queue at 22
	CPU 0: Dispatched process  8 at 22
Time slot  23---------------------------------
Time slot  24---------------------------------
	CPU 0: Put process  8 to run queue at 24
	CPU 0: Dispatched process  8 at 24
Time slot  25---------------------------------
	CPU 0: Processed  8 has finished at 25
	CPU 0: Dispatched process  7 at 25
Time slot  26---------------------------------
Time slot  27---------------------------------
	CPU 0: Put process  7 to run queue at 27
	CPU 0: Dispatched process  7 at 27
Time slot  28---------------------------------
Time slot  29---------------------------------
	CPU 0: Put process  7 to run queue at 29
	CPU 0: Dispatched process  7 at 29
Time slot  30---------------------------------
Time slot  31---------------------------------
	CPU 0: Put process  7 to run queue at 31
	CPU 0: Dispatched process  7 at 31
Time slot  32---------------------------------
Time slot  33---------------------------------
	CPU 0: Put process  7 to run queue at 33
	CPU 0: Dispatched process  7 at 33
Time slot  34---------------------------------
	CPU 0: Processed  7 has finished at 34
	CPU 0: Dispatched process  3 at 34
Time slot  35---------------------------------
Time slot  36---------------------------------
	CPU 0: Put process  3 to run queue at 36
	CPU 0: Dispatched process  6 at 36
Time slot  37---------------------------------
Time slot  38---------------------------------
	CPU 0: Put process  6 to run queue at 38
	CPU 0: Dispatched process  3 at 38
Time slot  39---------------------------------
	CPU 0: Processed  3 has finished at 39
	CPU 0: Dispatched process  6 at 39
Time slot  40---------------------------------
Time slot  41---------------------------------
	CPU 0: Put process  6 to run queue at 41
	CPU 0: Dispatched process  6 at 41
Time slot  42---------------------------------
Time slot  43---------------------------------
	CPU 0: Put process  6 to run queue at 43
	CPU 0: Dispatched process  6 at 43
Time slot  44---------------------------------
Time slot  45---------------------------------
	CPU 0: Processed  6 has finished at 45
	CPU 0: Dispatched process  4 at 45
Time slot  46---------------------------------
Time slot  47---------------------------------
	CPU 0: Put process  4 to run queue at 47
	CPU 0: Dispatched process  2 at 47
Time slot  48---------------------------------
Time slot  49---------------------------------
	CPU 0: Put process  2 to run queue at 49
	CPU 0: Dispatched process  5 at 49
SIZE 300
ALLOC SUCCESS 0 299
Time slot  50---------------------------------
SIZE 100
ALLOC SUCCESS 300 399
Time slot  51---------------------------------
	CPU 0: Put process  5 to run queue at 51
	CPU 0: Dispatched process  4 at 51
Time slot  52---------------------------------
Time slot  53---------------------------------
	CPU 0: Put process  4 to run queue at 53
	CPU 0: Dispatched process  2 at 53
Time slot  54---------------------------------
Time slot  55---------------------------------
	CPU 0: Put process  2 to run queue at 55
	CPU 0: Dispatched process  5 at 55
Time slot  56---------------------------------
ALLOC SUCCESS 0 99
Time slot  57---------------------------------
	CPU 0: Put process  5 to run queue at 57
	CPU 0: Dispatched process  4 at 57
Time slot  58---------------------------------
Time slot  59---------------------------------
	CPU 0: Put process  4 to run queue at 59
	CPU 0: Dispatched process  2 at 59
Time slot  60---------------------------------
Time slot  61---------------------------------
	CPU 0: Put process  2 to run queue at 61
	CPU 0: Dispatched process  5 at 61
SIZE 100
ALLOC SUCCESS 3145729 3145628
Time slot  62---------------------------------
write region=1 offset=20 value=102
PAGE TABLE FOR PROCESS 5************************
print_pgtbl for vmaid 0: 0 - 511
00000000: 80000003
00000004: 80000002
print_pgtbl for vmaid 1: 3145727 - 3145472
00049148: 80000004
********************************************

********************MEMPHY DUMP******************
frame: 4----------------------
frame: 2----------------------
frame: 3----------------------
frame: 0----------------------
frame: 1----------------------
***************************************************

Time slot  63---------------------------------
	CPU 0: Put process  5 to run queue at 63
	CPU 0: Dispatched process  4 at 63
Time slot  64---------------------------------
Time slot  65---------------------------------
	CPU 0: Put process  4 to run queue at 65
	CPU 0: Dispatched process  2 at 65
Time slot  66---------------------------------
	CPU 0: Processed  2 has finished at 66
	CPU 0: Dispatched process  5 at 66
write region=2 offset=1000 value=1
PAGE TABLE FOR PROCESS 5************************
print_pgtbl for vmaid 0: 0 - 511
00000000: 80000003
00000004: 80000002
print_pgtbl for vmaid 1: 3145727 - 3145472
00049148: 80000004
********************************************

********************MEMPHY DUMP******************
frame: 4----------------------
frame: 2----------------------
address 0x00000240: 102
frame: 3----------------------
frame: 0----------------------
frame: 1----------------------
***************************************************

Invalid
Time slot  67---------------------------------
	CPU 0: Processed  5 has finished at 67
	CPU 0: Dispatched process  4 at 67
Time slot  68---------------------------------
Time slot  69---------------------------------
	CPU 0: Put process  4 to run queue at 69
	CPU 0: Dispatched process  4 at 69
Time slot  70---------------------------------
Time slot  71---------------------------------
	CPU 0: Processed  4 has finished at 71
	CPU 0: Dispatched process  1 at 71
Time slot  72---------------------------------
Time slot  73---------------------------------
	CPU 0: Put process  1 to run queue at 73
	CPU 0: Dispatched process  1 at 73
Time slot  74---------------------------------
Time slot  75---------------------------------
	CPU 0: Put process  1 to run queue at 75
	CPU 0: Dispatched process  1 at 75
Time slot  76---------------------------------
Time slot  77---------------------------------
	CPU 0: Put process  1 to run queue at 77
	CPU 0: Dispatched process  1 at 77
Time slot  78---------------------------------
Time slot  79---------------------------------
	CPU 0: Put process  1 to run queue at 79
	CPU 0: Dispatched process  1 at 79
Time slot  80---------------------------------
Time slot  81---------------------------------
	CPU 0: Put process  1 to run queue at 81
	CPU 0: Dispatched process  1 at 81
Time slot  82---------------------------------
Time slot  83---------------------------------
	CPU 0: Put process  1 to run queue at 83
	CPU 0: Dispatched process  1 at 83
Time slot  84---------------------------------
Time slot  85---------------------------------
	CPU 0: Put process  1 to run queue at 85
	CPU 0: Dispatched process  1 at 85
Time slot  86---------------------------------
Time slot  87---------------------------------
	CPU 0: Put process  1 to run queue at 87
	CPU 0: Dispatched process  1 at 87
Time slot  88---------------------------------
Time slot  89---------------------------------
	CPU 0: Put process  1 to run queue at 89
	CPU 0: Dispatched process  1 at 89
Time slot  90---------------------------------
Time slot  91---------------------------------
	CPU 0: Put process  1 to run queue at 91
	CPU 0: Dispatched process  1 at 91
Time slot  92---------------------------------
Time slot  93---------------------------------
	CPU 0: Put process  1 to run queue at 93
	CPU 0: Dispatched process  1 at 93
Time slot  94---------------------------------
Time slot  95---------------------------------
	CPU 0: Put process  1 to run queue at 95
	CPU 0: Dispatched process  1 at 95
Time slot  96---------------------------------
Time slot  97---------------------------------
	CPU 0: Put process  1 to run queue at 97
	CPU 0: Dispatched process  1 at 97
Time slot  98---------------------------------
Time slot  99---------------------------------
	CPU 0: Put process  1 to run queue at 99
	CPU 0: Dispatched process  1 at 99
Time slot 100---------------------------------
Time slot 101---------------------------------
	CPU 0: Processed  1 has finished at 101
	CPU 0 stopped at 101
